Workbook
Name Chol: #REF!
Name Chol: #REF!
Name dt: GBM_Tesla!$B$7
Name dt: GBM_Apple!$B$7
Name Mu: GBM_Tesla!$B$4
Name Mu: GBM_Apple!$B$4
Name Sigma: GBM_Tesla!$B$5
Name Sigma: GBM_Apple!$B$5
Name Szero: GBM_Tesla!$B$3
Name Szero: GBM_Apple!$B$3

Sheet Question_1
A1: Date | B1: Tesla closing prices | C1: Daily returns on Tesla | D1: Apple closing prices | E1: Daily returns on Apple | M1: Tesla | N1: Apple
A2: 44200 | B2: 729.77002 | D2: 129.41 | L2: Expected return in a year | M2: =AVERAGE(C3:C252)*251 -> 0.53212057 | N2: =AVERAGE(E2:E52)*251 -> -0.12680328
A3: 44201 | B3: 735.10999 | C3: =(B3-B2)/B2 -> 0.0073173258 | D3: 131.01 | E3: =(D3-D2)/D2 -> 0.012363735 | L3: Volatility | M3: =_xlfn.STDEV.S(B2:B252)/AVERAGE(B2:B252) -> 0.20617098 | N3: =_xlfn.STDEV.S(D2:D252)/AVERAGE(D2:D252) -> 0.10298508
A4: 44202 | B4: 755.97998 | C4: =(B4-B3)/B3 -> 0.028390303 | D4: 126.6 | E4: =(D4-D3)/D3 -> -0.033661531
A5: 44203 | B5: 816.03998 | C5: =(B5-B4)/B4 -> 0.079446546 | D5: 130.92 | E5: =(D5-D4)/D4 -> 0.034123223
A6: 44204 | B6: 880.02002 | C6: =(B6-B5)/B5 -> 0.078403073 | D6: 132.05 | E6: =(D6-D5)/D5 -> 0.0086312635
A7: 44207 | B7: 811.19 | C7: =(B7-B6)/B6 -> -0.07821415 | D7: 128.98 | E7: =(D7-D6)/D6 -> -0.023248822
A8: 44208 | B8: 849.44 | C8: =(B8-B7)/B7 -> 0.047152948 | D8: 128.8 | E8: =(D8-D7)/D7 -> -0.001395511
A9: 44209 | B9: 854.40997 | C9: =(B9-B8)/B8 -> 0.0058508794 | D9: 130.89 | E9: =(D9-D8)/D8 -> 0.016226677
A10: 44210 | B10: 845 | C10: =(B10-B9)/B9 -> -0.011013417 | D10: 128.91 | E10: =(D10-D9)/D9 -> -0.015127168
A11: 44211 | B11: 826.15997 | C11: =(B11-B10)/B10 -> -0.02229589 | D11: 127.14 | E11: =(D11-D10)/D10 -> -0.013730548
A12: 44215 | B12: 844.54999 | C12: =(B12-B11)/B11 -> 0.02225963 | D12: 127.83 | E12: =(D12-D11)/D11 -> 0.0054271119
A13: 44216 | B13: 850.45001 | C13: =(B13-B12)/B12 -> 0.0069859974 | D13: 132.03 | E13: =(D13-D12)/D12 -> 0.032856113
A14: 44217 | B14: 844.98999 | C14: =(B14-B13)/B13 -> -0.0064201563 | D14: 136.86999 | E14: =(D14-D13)/D13 -> 0.036658305
A15: 44218 | B15: 846.64001 | C15: =(B15-B14)/B14 -> 0.0019527154 | D15: 139.07001 | E15: =(D15-D14)/D14 -> 0.016073735
... A252: 44560 | B252: 1070.34 | C252: =(B252-B251)/B251 -> -0.014592268 | D252: 178.2 | E252: =(D252-D251)/D251 -> -0.0065782583

Sheet Question_2
A1: Strike Price | B1: Call | C1: Put | H1: d1 | I1: N(d1) | J1: N'(d1) | L1: Price | O1: Call 165 | P1: Put 165 | Q1: Call 170 | R1: Put 170 | S1: Call 175 | T1: Put 175 | U1: Portfolio
A2: 165 | B2: 100 | C2: -50 | E2: time, t | F2: =1/12 -> 0.083333333 | H2: =(LN(170/A2)+(0.04+(0.35^2)/2)*(1/12)) / (0.35*SQRT(1/12)) -> 0.3789773 | I2: =_xlfn.NORM.DIST(H2, 0, 1, TRUE) -> 0.64764764 | J2: =(1/SQRTPI(2))*EXP((-H2^2)/2) -> 0.42864482 | L2: =170 -> 170 | N2: Delta | O2: =I2 -> 0.64764764 | P2: =O2 -1 -> -0.35235236 | Q2: =I3 -> 0.53327682 | R2: =Q2-1 -> -0.46672318 | S2: =I4 -> 0.41941409 | T2: =S2-1 -> -0.58058591 | U2: =B2*O2+C2*P2+B3*Q2+C3*R2+B4*S2+C4*T2 -> 158.71653
A3: 170 | B3: 150 | C3: -100 | E3: r | F3: =0.04 -> 0.04 | H3: =(LN(170/A3)+(0.04+(0.35^2)/2)*(1/12))/(0.35*SQRT(1/12)) -> 0.083509593 | I3: =_xlfn.NORM.DIST(H3, 0, 1, TRUE) -> 0.53327682 | J3: =(1/SQRTPI(2))*EXP((-H3^2)/2) -> 0.40033579 | L3: =175 -> 175 | N3: Gamma | O3: =J2/(170*F4*SQRT(1/12)) -> 0.024955785 | P3: 0.024955785 | Q3: =J3/(170*0.35*SQRT(1/12)) -> 0.023307628 | R3: 0.023307628 | S3: =J4/(170*0.35*SQRT(1/12)) -> 0.023711924 | T3: 0.023711924 | U3: =B2*O3+C2*P3+B3*Q3+(C3)*R3+B4*S3+C4*T3 -> -0.43226022
A4: 175 | B4: -120 | C4: 0 | E4: σ | F4: 0.35 | H4: =(LN(170/A4)+(0.04+(0.35^2)/2)*(1/12))/(0.35*SQRT(1/12)) -> -0.20339262 | I4: =_xlfn.NORM.DIST(H4, 0, 1, TRUE) -> 0.41941409 | J4: =(1/SQRTPI(2))*EXP((-H4^2)/2) -> 0.40728005 | L4: =165 -> 165 | N4: Vega | O4: =J2*170*SQRT(1/12) -> 21.035647 | P4: 21.035647 | Q4: =J3*170*SQRT(1/12) -> 19.646388 | R4: 19.646388 | S4: =J4*170*SQRT(1/12) -> 19.987176 | T4: 19.987176 | U4: =B2*O4+C2*P4+B3*Q4+C3*R4+B4*S4+C4*T4 -> -364.35934
X5: Increase in price to 175
X6: For Delta Neutral | Y6: Amount | Z6: Market Value
X7: Short | Y7: 158.7165 | Z7: =Y7*170 -> 26981.805
X8: Change in value | AB8: =0.5*U3*(175-170)^2 -> -5.4032527
X10: For Delta Gamma Neutral
X11: Long | Y11: =U3/Q3 -> -18.545869
X12: Buy | Y12: 18.5459
X13: Total Call options | Y13: =B3+Y12 -> 168.5459
X14: New Delta | Y14: =U2+Y12*Q2 -> 168.60663
X15: Short Stock | Y15: 168.60663 | Z15: =Y15*170 -> 28663.127
X16: Change in value | AB16: =0 -> 0
X18: Decrease in price to 165
X19: For Delta Neutral
X20: Change in value | AB20: =0.5*U3*(165-170)^2 -> -5.4032527
X21: For Delta Gamma Neutral | AB21: =0 -> 0

Sheet Question_3
B1: Apple | C1: Tesla | E1: Note that these values were calculated in Question_1 | L1: Date | M1: Tesla closing prices | N1: Scenario | P1: Change in Portfolio value Tesla | R1: CVaR | S1: Apple closing prices | T1: Scenario | V1: Change in Portfolio value Apple | Y1: CVaR | Z1: Change in Portfolio value Equal | AC1: CVaR
A2: Volatility | B2: 0.10298508 | C2: 0.20617098 | E2: From the emperical data we have 251 trading days instead of 252 | L2: 44200 | M2: 729.77002 | Q2: Sorted | R2: =AVERAGE(Q3:Q6) -> -91051.627 | S2: 129.41 | W2: Sorted | Y2: =AVERAGE(W3:W6) -> -60019.795 | AA2: Sorted | AC2: =AVERAGE(AA3:AA6) -> -67371.464
A3: Daily Volatility | B3: =B2/SQRT(251) -> 0.0065003607 | C3: =C2/SQRT(251) -> 0.013013397 | L3: 44201 | M3: 735.10999 | N3: 1 | O3: =1070.339966*M3/M2 -> 1078.172 | P3: =(1000000*O3/1070.339966)-1000000 -> 7317.3258 | Q3: {=_xlfn._xlws.SORT(P3:P252)} -> -119902.96 | S3: 131.01 | T3: 1 | U3: =174.199997*S3/S2 -> 176.35376 | V3: =(1000000*U3/178.199997)-1000000 -> -10360.479 | W3: {=_xlfn._xlws.SORT(V3:V252)} -> -63184.763 | Z3: =(500000*O3/1070.339966+500000*U3/178.199997)-1000000 -> -1521.5768 | AA3: {=_xlfn._xlws.SORT(Z3:Z252)} -> -69972.715
A4: Daily Volatility for $ 1 Million | B4: =1000000*B3 -> 6500.3607 | C4: =1000000*C3 -> 13013.397 | L4: 44202 | M4: 755.97998 | N4: 2 | O4: =1070.339966*M4/M3 -> 1100.7272 | P4: =(1000000*O4/1070.339966)-1000000 -> 28390.303 | Q4: -85498.514 | S4: 126.6 | T4: 2 | U4: =174.199997*S4/S3 -> 168.33616 | V4: =(1000000*U4/178.199997)-1000000 -> -55352.63 | W4: -60829.194 | Z4: =(500000*O4/1070.339966+500000*U4/178.199997)-1000000 -> -13481.164 | AA4: -68537.654
A5: 1-Day 99 VaR in Dollar value | B5: =B4*G6*-1 -> 15122.1 | C5: =C4*G6*-1 -> 30273.689 | E5: Assuming change is normally distrubted | L5: 44203 | M5: 816.03998 | N5: 3 | O5: =1070.339966*M5/M4 -> 1155.3748 | P5: =(1000000*O5/1070.339966)-1000000 -> 79446.546 | Q5: -80590.884 | S5: 130.92 | T5: 3 | U5: =174.199997*S5/S4 -> 180.14426 | V5: =(1000000*U5/178.199997)-1000000 -> 10910.58 | W5: -59027.314 | Z5: =(500000*O5/1070.339966+500000*U5/178.199997)-1000000 -> 45178.563 | AA5: -68519.714
E6: inverse of N(0.01) | G6: =NORMSINV(0.01) -> -2.3263479 | L6: 44204 | M6: 880.02002 | N6: 4 | O6: =1070.339966*M6/M5 -> 1154.2579 | P6: =(1000000*O6/1070.339966)-1000000 -> 78403.073 | Q6: -78214.15 | S6: 132.05 | T6: 4 | U6: =174.199997*S6/S5 -> 175.70356 | V6: =(1000000*U6/178.199997)-1000000 -> -14009.169 | W6: -57037.91 | Z6: =(500000*O6/1070.339966+500000*U6/178.199997)-1000000 -> 32196.952 | AA6: -62455.773
L7: 44207 | M7: 811.19 | N7: 5 | O7: =1070.339966*M7/M6 -> 986.62424 | P7: =(1000000*O7/1070.339966)-1000000 -> -78214.15 | Q7: -69320.792 | S7: 128.98 | T7: 5 | U7: =174.199997*S7/S6 -> 170.15005 | V7: =(1000000*U7/178.199997)-1000000 -> -45173.652 | W7: -56646.619 | Z7: =(500000*O7/1070.339966+500000*U7/178.199997)-1000000 -> -61693.901 | AA7: -61693.901
E8: Correlation Coefficient | H8: =CORREL(Question_1!E:E,Question_1!C:C) -> 0.45772171 | L8: 44208 | M8: 849.44 | N8: 6 | O8: =1070.339966*M8/M7 -> 1120.8097 | P8: =(1000000*O8/1070.339966)-1000000 -> 47152.948 | Q8: -64443.71 | S8: 128.8 | T8: 6 | U8: =174.199997*S8/S7 -> 173.9569 | V8: =(1000000*U8/178.199997)-1000000 -> -23810.876 | W8: -56448.544 | Z8: =(500000*O8/1070.339966+500000*U8/178.199997)-1000000 -> 11671.036 | AA8: -60817.243
L9: 44209 | M9: 854.40997 | N9: 7 | O9: =1070.339966*M9/M8 -> 1076.6024 | P9: =(1000000*O9/1070.339966)-1000000 -> 5850.8794 | Q9: -64198.789 | S9: 130.89 | T9: 7 | U9: =174.199997*S9/S8 -> 177.02668 | V9: =(1000000*U9/178.199997)-1000000 -> -6584.248 | W9: -55590.753 | Z9: =(500000*O9/1070.339966+500000*U9/178.199997)-1000000 -> -366.68432 | AA9: -56057.855
E10: Equally weighted protfolio | L10: 44210 | M10: 845 | N10: 8 | O10: =1070.339966*M10/M9 -> 1058.5519 | P10: =(1000000*O10/1070.339966)-1000000 -> -11013.417 | Q10: -60956.421 | S10: 128.91 | T10: 8 | U10: =174.199997*S10/S9 -> 171.56484 | V10: =(1000000*U10/178.199997)-1000000 -> -37234.303 | W10: -55352.63 | Z10: =(500000*O10/1070.339966+500000*U10/178.199997)-1000000 -> -24123.86 | AA10: -55553.178
E11: volatality | F11: =SQRT((B2^2)+(C2^2)+2*B2*C2*H8) -> 0.2693503 | L11: 44211 | M11: 826.15997 | N11: 9 | O11: =1070.339966*M11/M10 -> 1046.4758 | P11: =(1000000*O11/1070.339966)-1000000 -> -22295.89 | Q11: -58449.722 | S11: 127.14 | T11: 9 | U11: =174.199997*S11/S10 -> 171.80814 | V11: =(1000000*U11/178.199997)-1000000 -> -35869.032 | W11: -54805.536 | Z11: =(500000*O11/1070.339966+500000*U11/178.199997)-1000000 -> -29082.461 | AA11: -54590.542
E12: daily volatlility | G12: =F11/SQRT(251) -> 0.01700124 | L12: 44215 | M12: 844.54999 | N12: 10 | O12: =1070.339966*M12/M11 -> 1094.1653 | P12: =(1000000*O12/1070.339966)-1000000 -> 22259.63 | Q12: -53344.739 | S12: 127.83 | T12: 10 | U12: =174.199997*S12/S11 -> 175.1454 | V12: =(1000000*U12/178.199997)-1000000 -> -17141.398 | W12: -53414.037 | Z12: =(500000*O12/1070.339966+500000*U12/178.199997)-1000000 -> 2559.1157 | AA12: -49053.386
E13: daily volatlility for $ 1 million | H13: =G12*1000000 -> 17001.24 | L13: 44216 | M13: 850.45001 | N13: 11 | O13: =1070.339966*M13/M12 -> 1077.8174 | P13: =(1000000*O13/1070.339966)-1000000 -> 6985.9974 | Q13: -52551.049 | S13: 132.03 | T13: 11 | U13: =174.199997*S13/S12 -> 179.92353 | V13: =(1000000*U13/178.199997)-1000000 -> 9671.9126 | W13: -51576.793 | Z13: =(500000*O13/1070.339966+500000*U13/178.199997)-1000000 -> 8328.955 | AA13: -47389.009
E14: 1-Day 99 VaR in Dollar value | H14: =H13*G6*-1 -> 39550.8 | L14: 44217 | M14: 844.98999 | N14: 12 | O14: =1070.339966*M14/M13 -> 1063.4682 | P14: =(1000000*O14/1070.339966)-1000000 -> -6420.1563 | Q14: -50277.162 | S14: 136.86999 | T14: 12 | U14: =174.199997*S14/S13 -> 180.58587 | V14: =(1000000*U14/178.199997)-1000000 -> 13388.758 | W14: -48756.97 | Z14: =(500000*O14/1070.339966+500000*U14/178.199997)-1000000 -> 3484.3009 | AA14: -46214.645
L15: 44218 | M15: 846.64001 | N15: 13 | O15: =1070.339966*M15/M14 -> 1072.43 | P15: =(1000000*O15/1070.339966)-1000000 -> 1952.7154 | Q15: -50153.77 | S15: 139.07001 | T15: 13 | U15: =174.199997*S15/S14 -> 177.00004 | V15: =(1000000*U15/178.199997)-1000000 -> -6733.7568 | W15: -47672 | Z15: =(500000*O15/1070.339966+500000*U15/178.199997)-1000000 -> -2390.5207 | AA15: -45536.809
L16: 44221 | M16: 880.79999 | N16: 14 | O16: =1070.339966*M16/M15 -> 1113.5257 | P16: =(1000000*O16/1070.339966)-1000000 -> 40347.695 | Q16: -49772.43 | S16: 142.92 | T16: 14 | U16: =174.199997*S16/S15 -> 179.02252 | V16: =(1000000*U16/178.199997)-1000000 -> 4615.7342 | W16: -47375.314 | Z16: =(500000*O16/1070.339966+500000*U16/178.199997)-1000000 -> 22481.715 | AA16: -45075.955
L17: 44222 | M17: 883.09003 | N17: 15 | O17: =1070.339966*M17/M16 -> 1073.1228 | P17: =(1000000*O17/1070.339966)-1000000 -> 2599.9535 | Q17: -48622.182 | S17: 143.16 | T17: 15 | U17: =174.199997*S17/S16 -> 174.49253 | V17: =(1000000*U17/178.199997)-1000000 -> -20805.081 | W17: -46825.406 | Z17: =(500000*O17/1070.339966+500000*U17/178.199997)-1000000 -> -9102.5638 | AA17: -44946.377
L18: 44223 | M18: 864.15997 | N18: 16 | O18: =1070.339966*M18/M17 -> 1047.396 | P18: =(1000000*O18/1070.339966)-1000000 -> -21436.154 | Q18: -48423.737 | S18: 142.06 | T18: 16 | U18: =174.199997*S18/S17 -> 172.86149 | V18: =(1000000*U18/178.199997)-1000000 -> -29957.967 | W18: -46500.018 | Z18: =(500000*O18/1070.339966+500000*U18/178.199997)-1000000 -> -25697.061 | AA18: -43836.375
L19: 44224 | M19: 835.42999 | N19: 17 | O19: =1070.339966*M19/M18 -> 1034.7553 | P19: =(1000000*O19/1070.339966)-1000000 -> -33246.136 | Q19: -48400.712 | S19: 137.09 | T19: 17 | U19: =174.199997*S19/S18 -> 168.10557 | V19: =(1000000*U19/178.199997)-1000000 -> -56646.619 | W19: -46354.282 | Z19: =(500000*O19/1070.339966+500000*U19/178.199997)-1000000 -> -44946.377 | AA19: -43699.486
L20: 44225 | M20: 793.53003 | N20: 18 | O20: =1070.339966*M20/M19 -> 1016.6584 | P20: =(1000000*O20/1070.339966)-1000000 -> -50153.77 | Q20: -48160.496 | S20: 131.96001 | T20: 18 | U20: =174.199997*S20/S19 -> 167.68133 | V20: =(1000000*U20/178.199997)-1000000 -> -59027.314 | W20: -45713.703 | Z20: =(500000*O20/1070.339966+500000*U20/178.199997)-1000000 -> -54590.542 | AA20: -43262.926
L21: 44228 | M21: 839.81 | N21: 19 | O21: =1070.339966*M21/M20 -> 1132.7639 | P21: =(1000000*O21/1070.339966)-1000000 -> 58321.635 | Q21: -45326.499 | S21: 134.14 | T21: 19 | U21: =174.199997*S21/S20 -> 177.0778 | V21: =(1000000*U21/178.199997)-1000000 -> -6297.4148 | W21: -45173.652 | Z21: =(500000*O21/1070.339966+500000*U21/178.199997)-1000000 -> 26012.11 | AA21: -43153.267
L22: 44229 | M22: 872.78998 | N22: 20 | O22: =1070.339966*M22/M21 -> 1112.373 | P22: =(1000000*O22/1070.339966)-1000000 -> 39270.764 | Q22: -44527.638 | S22: 134.99 | T22: 20 | U22: =174.199997*S22/S21 -> 175.30385 | V22: =(1000000*U22/178.199997)-1000000 -> -16252.22 | W22: -43328.262 | Z22: =(500000*O22/1070.339966+500000*U22/178.199997)-1000000 -> 11509.272 | AA22: -41975.816
L23: 44230 | M23: 854.69 | N23: 21 | O23: =1070.339966*M23/M22 -> 1048.1432 | P23: =(1000000*O23/1070.339966)-1000000 -> -20738.066 | Q23: -44248.212 | S23: 133.94 | T23: 21 | U23: =174.199997*S23/S22 -> 172.845 | V23: =(1000000*U23/178.199997)-1000000 -> -30050.467 | W23: -42871.334 | Z23: =(500000*O23/1070.339966+500000*U23/178.199997)-1000000 -> -25394.266 | AA23: -40966.562
L24: 44231 | M24: 849.98999 | N24: 22 | O24: =1070.339966*M24/M23 -> 1064.4541 | P24: =(1000000*O24/1070.339966)-1000000 -> -5499.0839 | Q24: -43873.77 | S24: 137.39 | T24: 22 | U24: =174.199997*S24/S23 -> 178.687 | V24: =(1000000*U24/178.199997)-1000000 -> 2732.9129 | W24: -42656.86 | Z24: =(500000*O24/1070.339966+500000*U24/178.199997)-1000000 -> -1383.0855 | AA24: -39726.937
L25: 44232 | M25: 852.22998 | N25: 23 | O25: =1070.339966*M25/M24 -> 1073.1606 | P25: =(1000000*O25/1070.339966)-1000000 -> 2635.3134 | Q25: -43467.635 | S25: 136.76 | T25: 23 | U25: =174.199997*S25/S24 -> 173.4012 | V25: =(1000000*U25/178.199997)-1000000 -> -26929.276 | W25: -41991.413 | Z25: =(500000*O25/1070.339966+500000*U25/178.199997)-1000000 -> -12146.981 | AA25: -39716.287
L26: 44235 | M26: 863.41998 | N26: 24 | O26: =1070.339966*M26/M25 -> 1084.3938 | P26: =(1000000*O26/1070.339966)-1000000 -> 13130.262 | Q26: -43225.457 | S26: 136.91 | T26: 24 | U26: =174.199997*S26/S25 -> 174.39107 | V26: =(1000000*U26/178.199997)-1000000 -> -21374.433 | W26: -41179.725 | Z26: =(500000*O26/1070.339966+500000*U26/178.199997)-1000000 -> -4122.0854 | AA26: -39685.354
... L252: 44560 | M252: 1070.34 | N252: 250 | O252: =1070.339966*M252/M251 -> 1054.7213 | P252: =(1000000*O252/1070.339966)-1000000 -> -14592.268 | Q252: 196412.11 | S252: 178.2 | T252: 250 | U252: =174.199997*S252/S251 -> 173.05406 | V252: =(1000000*U252/178.199997)-1000000 -> -28877.288 | W252: 30195.749 | Z252: =(500000*O252/1070.339966+500000*U252/178.199997)-1000000 -> -21734.778 | AA252: 106851.32

Sheet Question_4
A1: Date | B1: BMO Close | C1: Scenario | E1: SUNCOR Close | F1: Scenario | H1: Shopify Close | I1: Scenario | K1: Change in portfolio value | N1: 10- Day VaR | Q1: Date | R1: BMO Close | T1: SUNCOR Close | V1: Shopify Close
A2: 43861 | B2: 76.220001 | E2: 30.59 | H2: 465.66 | L2: Sorted | Q2: 44134 | R2: 59.470001 | T2: 11.29 | V2: 925.42999 | Z2: Standard deviation | AA2: Mean
A3: 43864 | B3: 75.580002 | C3: 1 | D3: =143*B3/B2 -> 141.79927 | E3: 30.110001 | F3: 1 | G3: =29 *E3/E2 -> 28.54495 | H3: 469.39002 | I3: 1 | J3: =1206 *H3/H2 -> 1215.6603 | K3: =(1430*D3/143+435*G3/29+2412*J3/1206)-1430-435-2412 -> 0.48743114 | L3: {=_xlfn._xlws.SORT(K3:K505)} -> -689.99809 | N3: =L7*SQRT(10) -> -898.05807 | Q3: 44137 | R3: 60.110001 | S3: =(R3-R2)/R2 -> 0.010761728 | T3: 11.75 | U3: =(T3-T2)/T2 -> 0.040744021 | V3: 914.98999 | W3: =(V3-V2)/V2 -> -0.011281246 | Y3: BMO | Z3: =_xlfn.STDEV.S(S3:S316) -> 0.019270962 | AA3: =AVERAGE(S3:S316) -> 0.0029670067
A4: 43865 | B4: 76.269997 | C4: 2 | D4: =143*B4/B3 -> 144.30549 | E4: 30.030001 | F4: 2 | G4: =29 *E4/E3 -> 28.922949 | H4: 485.45999 | I4: 2 | J4: =1206 *H4/H3 -> 1247.2885 | K4: =(1430*D4/143+435*G4/29+2412*J4/1206)-1430-435-2412 -> 94.476105 | L4: -578.19248 | Q4: 44138 | R4: 61.990002 | S4: =(R4-R3)/R3 -> 0.03127601 | T4: 11.9 | U4: =(T4-T3)/T3 -> 0.012765957 | V4: 941.71997 | W4: =(V4-V3)/V3 -> 0.029213414 | Y4: Su | Z4: =_xlfn.STDEV.S(U3:U316) -> 0.029240915 | AA4: =AVERAGE(U3:U316) -> 0.0034187514
A5: 43866 | B5: 76.690002 | C5: 3 | D5: =143*B5/B4 -> 143.78747 | E5: 30.780001 | F5: 3 | G5: =29 *E5/E4 -> 29.724276 | H5: 475.56 | I5: 3 | J5: =1206 *H5/H4 -> 1181.406 | K5: =(1430*D5/143+435*G5/29+2412*J5/1206)-1430-435-2412 -> -30.449067 | L5: -575.56858 | Q5: 44139 | R5: 62.439999 | S5: =(R5-R4)/R4 -> 0.0072591867 | T5: 11.94 | U5: =(T5-T4)/T4 -> 0.0033613445 | V5: 996 | W5: =(V5-V4)/V4 -> 0.057639246 | Y5: Shop | Z5: =_xlfn.STDEV.S(W3:W316) -> 0.039779809 | AA5: =AVERAGE(W3:W316) -> 0.0015970212
A6: 43867 | B6: 77.050003 | C6: 4 | D6: =143*B6/B5 -> 143.67128 | E6: 29.690001 | F6: 4 | G6: =29 *E6/E5 -> 27.973034 | H6: 472.98001 | I6: 4 | J6: =1206 *H6/H5 -> 1199.4573 | K6: =(1430*D6/143+435*G6/29+2412*J6/1206)-1430-435-2412 -> -21.7772 | L6: -381.27359 | Q6: 44140 | R6: 62.919998 | S6: =(R6-R5)/R5 -> 0.007687364 | T6: 11.87 | U6: =(T6-T5)/T5 -> -0.0058626466 | V6: 1036.5 | W6: =(V6-V5)/V5 -> 0.040662651
A7: 43868 | B7: 77.040001 | C7: 5 | D7: =143*B7/B6 -> 142.98144 | E7: 29.1 | F7: 5 | G7: =29 *E7/E6 -> 28.423711 | H7: 478.69 | I7: 5 | J7: =1206 *H7/H6 -> 1220.5593 | K7: =(1430*D7/143+435*G7/29+2412*J7/1206)-1430-435-2412 -> 20.288593 | L7: -283.9909 | Q7: 44141 | R7: 62.360001 | S7: =(R7-R6)/R6 -> -0.0089001433 | T7: 11.71 | U7: =(T7-T6)/T6 -> -0.01347936 | V7: 1045 | W7: =(V7-V6)/V6 -> 0.0082006753
A8: 43871 | B8: 76.720001 | C8: 6 | D8: =143*B8/B7 -> 142.40602 | E8: 29.35 | F8: 6 | G8: =29 *E8/E7 -> 29.249141 | H8: 491.69 | I8: 6 | J8: =1206 *H8/H7 -> 1238.7519 | K8: =(1430*D8/143+435*G8/29+2412*J8/1206)-1430-435-2412 -> 63.301112 | L8: -277.50025 | Q8: 44144 | R8: 65.239998 | S8: =(R8-R7)/R7 -> 0.046183402 | T8: 14.54 | U8: =(T8-T7)/T7 -> 0.24167378 | V8: 902.59998 | W8: =(V8-V7)/V7 -> -0.13626797 | Z8: Correlation Matrix
A9: 43872 | B9: 76.900002 | C9: 7 | D9: =143*B9/B8 -> 143.33551 | E9: 29.41 | F9: 7 | G9: =29 *E9/E8 -> 29.059284 | H9: 492.75 | I9: 7 | J9: =1206 *H9/H8 -> 1208.5999 | K9: =(1430*D9/143+435*G9/29+2412*J9/1206)-1430-435-2412 -> 9.4441953 | L9: -245.54289 | Q9: 44145 | R9: 67.199997 | S9: =(R9-R8)/R8 -> 0.030042904 | T9: 14.62 | U9: =(T9-T8)/T8 -> 0.0055020633 | V9: 885.76001 | W9: =(V9-V8)/V8 -> -0.018657175 | Y9: 1
A10: 43873 | B10: 77 | C10: 8 | D10: =143*B10/B9 -> 143.18595 | E10: 29.549999 | F10: 8 | G10: =29 *E10/E9 -> 29.138047 | H10: 531.25 | I10: 8 | J10: =1206 *H10/H9 -> 1300.2283 | K10: =(1430*D10/143+435*G10/29+2412*J10/1206)-1430-435-2412 -> 192.38685 | L10: -239.0825 | Q10: 44146 | R10: 66.93 | S10: =(R10-R9)/R9 -> -0.0040178127 | T10: 14.62 | U10: =(T10-T9)/T9 -> 0 | V10: 947.17999 | W10: =(V10-V9)/V9 -> 0.069341562 | Y10: =CORREL(U3:U316, S3:S316) -> 0.40502569 | Z10: 1
A11: 43874 | B11: 76.730003 | C11: 9 | D11: =143*B11/B10 -> 142.49858 | E11: 29.51 | F11: 9 | G11: =29 *E11/E10 -> 28.960745 | H11: 532.96997 | I11: 9 | J11: =1206 *H11/H10 -> 1209.9045 | K11: =(1430*D11/143+435*G11/29+2412*J11/1206)-1430-435-2412 -> 2.2060253 | L11: -236.57842 | Q11: 44147 | R11: 66.050003 | S11: =(R11-R10)/R10 -> -0.01314802 | T11: 13.69 | U11: =(T11-T10)/T10 -> -0.063611491 | V11: 925.79999 | W11: =(V11-V10)/V10 -> -0.022572273 | Y11: =CORREL(S3:S316, W3:W316) -> 0.44176033 | Z11: =CORREL(W3:W316, U3:U316) -> -0.01514417 | AA11: 1
A12: 43875 | B12: 76.839996 | C12: 10 | D12: =143*B12/B11 -> 143.20499 | E12: 29.780001 | F12: 10 | G12: =29 *E12/E11 -> 29.265335 | H12: 531.21997 | I12: 10 | J12: =1206 *H12/H11 -> 1202.0401 | K12: =(1430*D12/143+435*G12/29+2412*J12/1206)-1430-435-2412 -> -1.8898342 | L12: -229.88846 | Q12: 44148 | R12: 66.669998 | S12: =(R12-R11)/R11 -> 0.009386752 | T12: 13.91 | U12: =(T12-T11)/T11 -> 0.016070124 | V12: 918.29999 | W12: =(V12-V11)/V11 -> -0.0081011019
A13: 43879 | B13: 76.459999 | C13: 11 | D13: =143*B13/B12 -> 142.29282 | E13: 30 | F13: 11 | G13: =29 *E13/E12 -> 29.214237 | H13: 536.40997 | I13: 11 | J13: =1206 *H13/H12 -> 1217.7826 | K13: =(1430*D13/143+435*G13/29+2412*J13/1206)-1430-435-2412 -> 19.706932 | L13: -221.37977 | Q13: 44151 | R13: 68.639999 | S13: =(R13-R12)/R12 -> 0.029548538 | T13: 14.98 | U13: =(T13-T12)/T12 -> 0.076923077 | V13: 919.21997 | W13: =(V13-V12)/V12 -> 0.0010018327
A14: 43880 | B14: 76.419998 | C14: 12 | D14: =143*B14/B13 -> 142.92519 | E14: 30.48 | F14: 12 | G14: =29 *E14/E13 -> 29.464 | H14: 543.21002 | I14: 12 | J14: =1206 *H14/H13 -> 1221.2884 | K14: =(1430*D14/143+435*G14/29+2412*J14/1206)-1430-435-2412 -> 36.788711 | L14: -217.42153 | Q14: 44152 | R14: 69.400002 | S14: =(R14-R13)/R13 -> 0.011072305 | T14: 15.25 | U14: =(T14-T13)/T13 -> 0.018024032 | V14: 914.02002 | W14: =(V14-V13)/V13 -> -0.0056569169 | Y14: Weight vector
A15: 43881 | B15: 76.32 | C15: 13 | D15: =143*B15/B14 -> 142.81288 | E15: 30.459999 | F15: 13 | G15: =29 *E15/E14 -> 28.98097 | H15: 535.58002 | I15: 13 | J15: =1206 *H15/H14 -> 1189.0604 | K15: =(1430*D15/143+435*G15/29+2412*J15/1206)-1430-435-2412 -> -36.035942 | L15: -207.38956 | Q15: 44153 | R15: 69.949997 | S15: =(R15-R14)/R14 -> 0.0079249998 | T15: 15.36 | U15: =(T15-T14)/T14 -> 0.0072131148 | V15: 931.42999 | W15: =(V15-V14)/V14 -> 0.019047693 | Y15: 0.334
A16: 43882 | B16: 76.470001 | C16: 14 | D16: =143*B16/B15 -> 143.28106 | E16: 30.389999 | F16: 14 | G16: =29 *E16/E15 -> 28.933355 | H16: 520.65997 | I16: 14 | J16: =1206 *H16/H15 -> 1172.4036 | K16: =(1430*D16/143+435*G16/29+2412*J16/1206)-1430-435-2412 -> -65.381965 | L16: -202.42011 | Q16: 44154 | R16: 70.68 | S16: =(R16-R15)/R15 -> 0.010436069 | T16: 15.44 | U16: =(T16-T15)/T15 -> 0.0052083333 | V16: 966.77002 | W16: =(V16-V15)/V15 -> 0.037941689 | Y16: 0.102
A17: 43885 | B17: 74.860001 | C17: 15 | D17: =143*B17/B16 -> 139.98928 | E17: 29.379999 | F17: 15 | G17: =29 *E17/E16 -> 28.036196 | H17: 490.95999 | I17: 15 | J17: =1206 *H17/H16 -> 1137.2062 | K17: =(1430*D17/143+435*G17/29+2412*J17/1206)-1430-435-2412 -> -182.15189 | L17: -198.90458 | Q17: 44155 | R17: 71.339996 | S17: =(R17-R16)/R16 -> 0.0093378042 | T17: 15.41 | U17: =(T17-T16)/T16 -> -0.0019430052 | V17: 988.51001 | W17: =(V17-V16)/V16 -> 0.022487241 | Y17: 0.564
A18: 43886 | B18: 73.010002 | C18: 16 | D18: =143*B18/B17 -> 139.46607 | E18: 29.120001 | F18: 16 | G18: =29 *E18/E17 -> 28.743365 | H18: 466.45999 | I18: 16 | J18: =1206 *H18/H17 -> 1145.8179 | K18: =(1430*D18/143+435*G18/29+2412*J18/1206)-1430-435-2412 -> -159.553 | L18: -190.26011 | Q18: 44158 | R18: 72.580002 | S18: =(R18-R17)/R17 -> 0.017381638 | T18: 16.76 | U18: =(T18-T17)/T17 -> 0.087605451 | V18: 980.01001 | W18: =(V18-V17)/V17 -> -0.0085988001
A19: 43887 | B19: 71.650002 | C19: 17 | D19: =143*B19/B18 -> 140.33626 | E19: 28.440001 | F19: 17 | G19: =29 *E19/E18 -> 28.322802 | H19: 471.17999 | I19: 17 | J19: =1206 *H19/H18 -> 1218.2032 | K19: =(1430*D19/143+435*G19/29+2412*J19/1206)-1430-435-2412 -> -12.388936 | L19: -185.15465 | Q19: 44159 | R19: 74.809998 | S19: =(R19-R18)/R18 -> 0.030724662 | T19: 17.67 | U19: =(T19-T18)/T18 -> 0.054295943 | V19: 971.23999 | W19: =(V19-V18)/V18 -> -0.0089489086
A20: 43888 | B20: 69.160004 | C20: 18 | D20: =143*B20/B19 -> 138.03043 | E20: 27.639999 | F20: 18 | G20: =29 *E20/E19 -> 28.184246 | H20: 438.37 | I20: 18 | J20: =1206 *H20/H19 -> 1122.0218 | K20: =(1430*D20/143+435*G20/29+2412*J20/1206)-1430-435-2412 -> -229.88846 | L20: -182.15189 | Q20: 44160 | R20: 74.809998 | S20: =(R20-R19)/R19 -> 0 | T20: 17.559999 | U20: =(T20-T19)/T19 -> -0.0062252971 | V20: 1019.52 | W20: =(V20-V19)/V19 -> 0.049709681
A21: 43889 | B21: 67.879997 | C21: 19 | D21: =143*B21/B20 -> 140.35337 | E21: 27.6 | F21: 19 | G21: =29 *E21/E20 -> 28.958033 | H21: 463.31 | I21: 19 | J21: =1206 *H21/H20 -> 1274.6125 | K21: =(1430*D21/143+435*G21/29+2412*J21/1206)-1430-435-2412 -> 110.1291 | L21: -166.94607 | Q21: 44162 | R21: 74.739998 | S21: =(R21-R20)/R20 -> -0.00093570381 | T21: 17.25 | U21: =(T21-T20)/T20 -> -0.017653703 | V21: 1034.39 | W21: =(V21-V20)/V20 -> 0.01458529
A22: 43892 | B22: 69.099998 | C22: 20 | D22: =143*B22/B21 -> 145.57013 | E22: 27.700001 | F22: 20 | G22: =29 *E22/E21 -> 29.105074 | H22: 488.39999 | I22: 20 | J22: =1206 *H22/H21 -> 1271.3095 | K22: =(1430*D22/143+435*G22/29+2412*J22/1206)-1430-435-2412 -> 157.89632 | L22: -166.06299 | Q22: 44165 | R22: 72.720001 | S22: =(R22-R21)/R21 -> -0.027026988 | T22: 16.09 | U22: =(T22-T21)/T21 -> -0.067246377 | V22: 1090.38 | W22: =(V22-V21)/V21 -> 0.05412851
A23: 43893 | B23: 67.239998 | C23: 21 | D23: =143*B23/B22 -> 139.1508 | E23: 26.370001 | F23: 21 | G23: =29 *E23/E22 -> 27.607581 | H23: 476.94 | I23: 21 | J23: =1206 *H23/H22 -> 1177.702 | K23: =(1430*D23/143+435*G23/29+2412*J23/1206)-1430-435-2412 -> -115.97435 | L23: -162.27516 | Q23: 44166 | R23: 74.589996 | S23: =(R23-R22)/R22 -> 0.025715002 | T23: 15.95 | U23: =(T23-T22)/T22 -> -0.0087010566 | V23: 1069.0601 | W23: =(V23-V22)/V22 -> -0.019552767
A24: 43894 | B24: 67.870003 | C24: 22 | D24: =143*B24/B23 -> 144.33984 | E24: 26.709999 | F24: 22 | G24: =29 *E24/E23 -> 29.373908 | H24: 512.22998 | I24: 22 | J24: =1206 *H24/H23 -> 1295.2349 | K24: =(1430*D24/143+435*G24/29+2412*J24/1206)-1430-435-2412 -> 197.47688 | L24: -161.80521 | Q24: 44167 | R24: 75.32 | S24: =(R24-R23)/R23 -> 0.0097868888 | T24: 16.219999 | U24: =(T24-T23)/T23 -> 0.016927837 | V24: 1079.4399 | W24: =(V24-V23)/V23 -> 0.0097093535
A25: 43895 | B25: 65.540001 | C25: 23 | D25: =143*B25/B24 -> 138.09076 | E25: 25.969999 | F25: 23 | G25: =29 *E25/E24 -> 28.196556 | H25: 498.22 | I25: 23 | J25: =1206 *H25/H24 -> 1173.0147 | K25: =(1430*D25/143+435*G25/29+2412*J25/1206)-1430-435-2412 -> -127.11459 | L25: -160.39552 | Q25: 44168 | R25: 75.900002 | S25: =(R25-R24)/R24 -> 0.0077005045 | T25: 16.6 | U25: =(T25-T24)/T24 -> 0.02342793 | V25: 1062.6801 | W25: =(V25-V24)/V24 -> -0.015526465
A26: 43896 | B26: 62.939999 | C26: 24 | D26: =143*B26/B25 -> 137.32712 | E26: 25.040001 | F26: 24 | G26: =29 *E26/E25 -> 27.961496 | H26: 472.07001 | I26: 24 | J26: =1206 *H26/H25 -> 1142.7009 | K26: =(1430*D26/143+435*G26/29+2412*J26/1206)-1430-435-2412 -> -198.90458 | L26: -159.553 | Q26: 44169 | R26: 76.779999 | S26: =(R26-R25)/R25 -> 0.011594163 | T26: 17.98 | U26: =(T26-T25)/T25 -> 0.08313253 | V26: 1053.89 | W26: =(V26-V25)/V25 -> -0.0082715762
A27: 43899 | B27: 53.380001 | C27: 25 | D27: =143*B27/B26 -> 121.27964 | E27: 20.219999 | F27: 25 | G27: =29 *E27/E26 -> 23.41773 | H27: 418.32001 | I27: 25 | J27: =1206 *H27/H26 -> 1068.6846 | K27: =(1430*D27/143+435*G27/29+2412*J27/1206)-1430-435-2412 -> -575.56858 | L27: -157.50797 | Q27: 44172 | R27: 76.089996 | S27: =(R27-R26)/R26 -> -0.0089867545 | T27: 17.860001 | U27: =(T27-T26)/T26 -> -0.0066740267 | V27: 1084.4 | W27: =(V27-V26)/V26 -> 0.028949899
A28: 43900 | B28: 55.240002 | C28: 26 | D28: =143*B28/B27 -> 147.98277 | E28: 20.209999 | F28: 26 | G28: =29 *E28/E27 -> 28.985658 | H28: 450.34 | I28: 26 | J28: =1206 *H28/H27 -> 1298.3124 | K28: =(1430*D28/143+435*G28/29+2412*J28/1206)-1430-435-2412 -> 234.23726 | L28: -155.50402 | Q28: 44173 | R28: 76.269997 | S28: =(R28-R27)/R27 -> 0.0023656329 | T28: 18.23 | U28: =(T28-T27)/T27 -> 0.020716628 | V28: 1102.09 | W28: =(V28-V27)/V27 -> 0.016313115
A29: 43901 | B29: 52.66 | C29: 27 | D29: =143*B29/B28 -> 136.32114 | E29: 18.879999 | F29: 27 | G29: =29 *E29/E28 -> 27.091539 | H29: 422.31 | I29: 27 | J29: =1206 *H29/H28 -> 1130.9363 | K29: =(1430*D29/143+435*G29/29+2412*J29/1206)-1430-435-2412 -> -245.54289 | L29: -153.44795 | Q29: 44174 | R29: 76.730003 | S29: =(R29-R28)/R28 -> 0.0060312838 | T29: 17.99 | U29: =(T29-T28)/T28 -> -0.013165112 | V29: 1038.1899 | W29: =(V29-V28)/V28 -> -0.05798077
... A316: 44316 | B316: 94.339996 | C316: 314 | D316: =143*B316/B315 -> 141.14479 | E316: 21.42 | F316: 314 | G316: =29 *E316/E315 -> 28.546875 | H316: 1182.51 | I316: 314 | J316: =1206 *H316/H315 -> 1156.55 | K316: =(1430*D316/143+435*G316/29+2412*J316/1206)-1430-435-2412 -> -124.24892 | L316: 31.435745 | Q316: 44592 | R316: 143 | S316: =(R316-R315)/R315 -> 0.26481516 | T316: 29 | U316: =(T316-T315)/T315 -> 0.024735019 | V316: 1209 | W316: =(V316-V315)/V315 -> 0.38610232
A317: 44319 | B317: 94.32 | C317: 315 | D317: =143*B317/B316 -> 142.96969 | E317: 21.940001 | F317: 315 | G317: =29 *E317/E316 -> 29.704016 | H317: 1122.01 | I317: 315 | J317: =1206 *H317/H316 -> 1144.2982 | K317: =(1430*D317/143+435*G317/29+2412*J317/1206)-1430-435-2412 -> -113.14646 | L317: 32.189127
A318: 44320 | B318: 93.93 | C318: 316 | D318: =143*B318/B317 -> 142.40872 | E318: 21.889999 | F318: 316 | G318: =29 *E318/E317 -> 28.933908 | H318: 1142.9399 | I318: 316 | J318: =1206 *H318/H317 -> 1228.4967 | K318: =(1430*D318/143+435*G318/29+2412*J318/1206)-1430-435-2412 -> 38.089125 | L318: 32.324874
A319: 44321 | B319: 94.760002 | C319: 317 | D319: =143*B319/B318 -> 144.2636 | E319: 22.75 | F319: 317 | G319: =29 *E319/E318 -> 30.139334 | H319: 1120.35 | I319: 317 | J319: =1206 *H319/H318 -> 1182.1637 | K319: =(1430*D319/143+435*G319/29+2412*J319/1206)-1430-435-2412 -> -17.946615 | L319: 32.791262
A320: 44322 | B320: 96.449997 | C320: 318 | D320: =143*B320/B319 -> 145.55033 | E320: 22.99 | F320: 318 | G320: =29 *E320/E319 -> 29.305934 | H320: 1090.9301 | I320: 318 | J320: =1206 *H320/H319 -> 1174.3309 | K320: =(1430*D320/143+435*G320/29+2412*J320/1206)-1430-435-2412 -> -33.2458 | L320: 32.832077
A321: 44323 | B321: 97.089996 | C321: 319 | D321: =143*B321/B320 -> 143.94888 | E321: 23.629999 | F321: 319 | G321: =29 *E321/E320 -> 29.807306 | H321: 1108.6 | I321: 319 | J321: =1206 *H321/H320 -> 1225.5337 | K321: =(1430*D321/143+435*G321/29+2412*J321/1206)-1430-435-2412 -> 60.665881 | L321: 33.161361
A322: 44326 | B322: 97.470001 | C322: 320 | D322: =143*B322/B321 -> 143.55969 | E322: 23.34 | F322: 320 | G322: =29 *E322/E321 -> 28.644098 | H322: 1080.24 | I322: 320 | J322: =1206 *H322/H321 -> 1175.1483 | K322: =(1430*D322/143+435*G322/29+2412*J322/1206)-1430-435-2412 -> -61.4449 | L322: 33.77219
A323: 44327 | B323: 96.800003 | C323: 321 | D323: =143*B323/B322 -> 142.01703 | E323: 22.889999 | F323: 321 | G323: =29 *E323/E322 -> 28.440873 | H323: 1110.2 | I323: 321 | J323: =1206 *H323/H322 -> 1239.4479 | K323: =(1430*D323/143+435*G323/29+2412*J323/1206)-1430-435-2412 -> 48.679145 | L323: 34.218779
A324: 44328 | B324: 96.010002 | C324: 322 | D324: =143*B324/B323 -> 141.83295 | E324: 23.299999 | F324: 322 | G324: =29 *E324/E323 -> 29.519441 | H324: 1083.9 | I324: 322 | J324: =1206 *H324/H323 -> 1177.4306 | K324: =(1430*D324/143+435*G324/29+2412*J324/1206)-1430-435-2412 -> -61.017594 | L324: 34.682132
A325: 44329 | B325: 98.199997 | C325: 323 | D325: =143*B325/B324 -> 146.26184 | E325: 22.629999 | F325: 323 | G325: =29 *E325/E324 -> 28.166094 | H325: 1047.77 | I325: 323 | J325: =1206 *H325/H324 -> 1165.8 | K325: =(1430*D325/143+435*G325/29+2412*J325/1206)-1430-435-2412 -> -60.290189 | L325: 36.788711
A326: 44330 | B326: 99.580002 | C326: 324 | D326: =143*B326/B325 -> 145.00958 | E326: 23.23 | F326: 324 | G326: =29 *E326/E325 -> 29.768892 | H326: 1085.01 | I326: 324 | J326: =1206 *H326/H325 -> 1248.8638 | K326: =(1430*D326/143+435*G326/29+2412*J326/1206)-1430-435-2412 -> 117.35682 | L326: 37.326016
...

Sheet Question_5
A1: Moodys
A2: Term(Years) | B2: 1 | C2: 2 | D2: 3 | E2: 4 | F2: 5
A3: Ba | B3: =1.112/100 -> 0.01112 | C3: =3.083/100 -> 0.03083 | D3: =5.424/100 -> 0.05424 | E3: =7.934/100 -> 0.07934 | F3: =10.189/100 -> 0.10189
A4: Unconditional | C4: =C3-B3 -> 0.01971 | D4: =D3-C3 -> 0.02341 | E4: =E3-D3 -> 0.0251 | F4: =F3-E3 -> 0.02255
A5: hazard rate | C5: =C4/(1-B3) -> 0.01993164 | D5: =D4/(1-C3) -> 0.024154689 | E5: =E4/(1-D3) -> 0.026539503 | F5: =F4/(1-E3) -> 0.024493298
A6: average hazard rate | G6: =AVERAGE(C5:F5) -> 0.023779782
A7: Q(t) | B7: =1 - EXP(-1*G6*B2) -> 0.023499271 | C7: =1 - EXP(-1*0.02378*C2) -> 0.046446742 | D7: =1 - EXP(-1*0.02378*D2) -> 0.068854751 | E7: =1 - EXP(-1*0.02378*E2) -> 0.090736184 | F7: =1 - EXP(-1*0.02378*F2) -> 0.11210341

Sheet GBM_Apple
A1: Geometric Brownian motion: illustration
A3: Initial price S | B3: =Question_1!$D$2 -> 129.41
A4: Drift m | B4: =Question_1!$N$2 -> -0.12680328
A5: Volatilty s | B5: =Question_1!$N$3 -> 0.10298508
A6: # steps /year | B6: 52
A7: TimeStep Dt | B7: =1/B6 -> 0.019230769
B8: <=========Drift==================> | E8: <=== ===Random component========>
B9: Drift component | C9: Non stoch. Evolution | I9: Cumulated random shocks
A10: Period | B10: mDt | C10: S0+SmS0Dt | D10: mSDt | E10: N(0,1) | F10: Dz | G10: sDz | H10: sSDz | I10: SsSDz | J10: DS | K10: S
A11: 0 | C11: =Szero -> 129.41 | I11: 0 | K11: =B3 -> 129.41
A12: 1 | B12: =Mu*dt -> -0.0024385246 | C12: =C11*(1+B12) -> 129.09443 | D12: =K11*B12 -> -0.31556948 | E12: =NORMINV(RAND(),0,1) -> 0.59041552 | F12: =E12*SQRT(dt) -> 0.081875901 | G12: =Sigma*F12 -> 0.0084319963 | H12: =G12*K11 -> 1.0911847 | I12: =I11+H12 -> 1.0911847 | J12: =D12+H12 -> 0.77561519 | K12: =K11+J12 -> 130.18562
A13: 2 | B13: =Mu*dt -> -0.0024385246 | C13: =C12*(1+B13) -> 128.77963 | D13: =K12*B13 -> -0.31746084 | E13: =NORMINV(RAND(),0,1) -> -1.0144608 | F13: =E13*SQRT(dt) -> -0.1406804 | G13: =Sigma*F13 -> -0.014487983 | H13: =G13*K12 -> -1.886127 | I13: =I12+H13 -> -0.79494235 | J13: =D13+H13 -> -2.2035879 | K13: =K12+J13 -> 127.98203
A14: 3 | B14: =Mu*dt -> -0.0024385246 | C14: =C13*(1+B14) -> 128.4656 | D14: =K13*B14 -> -0.31208734 | E14: =NORMINV(RAND(),0,1) -> 0.49491592 | F14: =E14*SQRT(dt) -> 0.068632489 | G14: =Sigma*F14 -> 0.0070681224 | H14: =G14*K13 -> 0.90459267 | I14: =I13+H14 -> 0.10965032 | J14: =D14+H14 -> 0.59250533 | K14: =K13+J14 -> 128.57454
A15: 4 | B15: =Mu*dt -> -0.0024385246 | C15: =C14*(1+B15) -> 128.15234 | D15: =K14*B15 -> -0.31353218 | E15: =NORMINV(RAND(),0,1) -> 0.038188212 | F15: =E15*SQRT(dt) -> 0.0052957521 | G15: =Sigma*F15 -> 0.00054538346 | H15: =G15*K14 -> 0.070122426 | I15: =I14+H15 -> 0.17977274 | J15: =D15+H15 -> -0.24340975 | K15: =K14+J15 -> 128.33113
A16: 5 | B16: =Mu*dt -> -0.0024385246 | C16: =C15*(1+B16) -> 127.83983 | D16: =K15*B16 -> -0.31293862 | E16: =NORMINV(RAND(),0,1) -> 0.14475487 | F16: =E16*SQRT(dt) -> 0.020073888 | G16: =Sigma*F16 -> 0.002067311 | H16: =G16*K15 -> 0.26530035 | I16: =I15+H16 -> 0.4450731 | J16: =D16+H16 -> -0.047638263 | K16: =K15+J16 -> 128.28349
A17: 6 | B17: =Mu*dt -> -0.0024385246 | C17: =C16*(1+B17) -> 127.52809 | D17: =K16*B17 -> -0.31282245 | E17: =NORMINV(RAND(),0,1) -> 0.7906373 | F17: =E17*SQRT(dt) -> 0.10964167 | G17: =Sigma*F17 -> 0.011291456 | H17: =G17*K16 -> 1.4485074 | I17: =I16+H17 -> 1.8935805 | J17: =D17+H17 -> 1.1356849 | K17: =K16+J17 -> 129.41917
A18: 7 | B18: =Mu*dt -> -0.0024385246 | C18: =C17*(1+B18) -> 127.21711 | D18: =K17*B18 -> -0.31559184 | E18: =NORMINV(RAND(),0,1) -> 0.087992875 | F18: =E18*SQRT(dt) -> 0.012202416 | G18: =Sigma*F18 -> 0.0012566668 | H18: =G18*K17 -> 0.16263678 | I18: =I17+H18 -> 2.0562172 | J18: =D18+H18 -> -0.15295506 | K18: =K17+J18 -> 129.26622
A19: 8 | B19: =Mu*dt -> -0.0024385246 | C19: =C18*(1+B19) -> 126.90689 | D19: =K18*B19 -> -0.31521886 | E19: =NORMINV(RAND(),0,1) -> -2.0026259 | F19: =E19*SQRT(dt) -> -0.27771424 | G19: =Sigma*F19 -> -0.028600423 | H19: =G19*K18 -> -3.6970686 | I19: =I18+H19 -> -1.6408513 | J19: =D19+H19 -> -4.0122874 | K19: =K18+J19 -> 125.25393
A20: 9 | B20: =Mu*dt -> -0.0024385246 | C20: =C19*(1+B20) -> 126.59742 | D20: =K19*B20 -> -0.3054348 | E20: =NORMINV(RAND(),0,1) -> -0.39173838 | F20: =E20*SQRT(dt) -> -0.054324339 | G20: =Sigma*F20 -> -0.0055945964 | H20: =G20*K19 -> -0.70074519 | I20: =I19+H20 -> -2.3415965 | J20: =D20+H20 -> -1.00618 | K20: =K19+J20 -> 124.24775
A21: 10 | B21: =Mu*dt -> -0.0024385246 | C21: =C20*(1+B21) -> 126.28871 | D21: =K20*B21 -> -0.3029812 | E21: =NORMINV(RAND(),0,1) -> 0.32691048 | F21: =E21*SQRT(dt) -> 0.045334327 | G21: =Sigma*F21 -> 0.0046687593 | H21: =G21*K20 -> 0.58008284 | I21: =I20+H21 -> -1.7615137 | J21: =D21+H21 -> 0.27710164 | K21: =K20+J21 -> 124.52485
A22: 11 | B22: =Mu*dt -> -0.0024385246 | C22: =C21*(1+B22) -> 125.98076 | D22: =K21*B22 -> -0.30365692 | E22: =NORMINV(RAND(),0,1) -> 1.2647894 | F22: =E22*SQRT(dt) -> 0.17539473 | G22: =Sigma*F22 -> 0.018063041 | H22: =G22*K21 -> 2.2492975 | I22: =I21+H22 -> 0.48778377 | J22: =D22+H22 -> 1.9456405 | K22: =K21+J22 -> 126.47049
A23: 12 | B23: =Mu*dt -> -0.0024385246 | C23: =C22*(1+B23) -> 125.67355 | D23: =K22*B23 -> -0.30840141 | E23: =NORMINV(RAND(),0,1) -> 0.55707094 | F23: =E23*SQRT(dt) -> 0.07725184 | G23: =Sigma*F23 -> 0.007955787 | H23: =G23*K22 -> 1.0061723 | I23: =I22+H23 -> 1.4939561 | J23: =D23+H23 -> 0.69777089 | K23: =K22+J23 -> 127.16826
... A51: 40 | B51: =Mu*dt -> -0.0024385246 | C51: =C50*(1+B51) -> 117.36932 | D51: =K50*B51 -> -0.33718157 | E51: =NORMINV(RAND(),0,1) -> 0.019850096 | F51: =E51*SQRT(dt) -> 0.002752713 | G51: =Sigma*F51 -> 0.00028348837 | H51: =G51*K50 -> 0.039198724 | I51: =I50+H51 -> 21.398566 | J51: =D51+H51 -> -0.29798285 | K51: =K50+J51 -> 137.97479

Sheet GBM_Tesla
A1: Geometric Brownian motion: illustration
A3: Initial price S | B3: =Question_1!$B$2 -> 729.77002
A4: Drift m | B4: =Question_1!$M$2 -> 0.53212057
A5: Volatilty s | B5: =Question_1!$M$3 -> 0.20617098
A6: # steps /year | B6: 52
A7: TimeStep Dt | B7: =1/B6 -> 0.019230769
B8: <=========Drift==================> | E8: <=== ===Random component========>
B9: Drift component | C9: Non stoch. Evolution | I9: Cumulated random shocks
A10: Period | B10: mDt | C10: S0+SmS0Dt | D10: mSDt | E10: N(0,1) | F10: Dz | G10: sDz | H10: sSDz | I10: SsSDz | J10: DS | K10: S
A11: 0 | C11: =Szero -> 729.77002 | I11: 0 | K11: =B3 -> 729.77002
A12: 1 | B12: =Mu*dt -> 0.010233088 | C12: =C11*(1+B12) -> 737.23782 | D12: =K11*B12 -> 7.4678007 | E12: =NORMINV(RAND(),0,1) -> 4.3222917 | F12: =E12*SQRT(dt) -> 0.59939401 | G12: =Sigma*F12 -> 0.12357765 | H12: =G12*K11 -> 90.183266 | I12: =I11+H12 -> 90.183266 | J12: =D12+H12 -> 97.651067 | K12: =K11+J12 -> 827.42109
A13: 2 | B13: =Mu*dt -> 0.010233088 | C13: =C12*(1+B13) -> 744.78204 | D13: =K12*B13 -> 8.4670726 | E13: =NORMINV(RAND(),0,1) -> -0.53032009 | F13: =E13*SQRT(dt) -> -0.073542164 | G13: =Sigma*F13 -> -0.01516226 | H13: =G13*K12 -> -12.545574 | I13: =I12+H13 -> 77.637692 | J13: =D13+H13 -> -4.0785013 | K13: =K12+J13 -> 823.34259
A14: 3 | B14: =Mu*dt -> 0.010233088 | C14: =C13*(1+B14) -> 752.40346 | D14: =K13*B14 -> 8.425337 | E14: =NORMINV(RAND(),0,1) -> -0.23640233 | F14: =E14*SQRT(dt) -> -0.032783104 | G14: =Sigma*F14 -> -0.0067589249 | H14: =G14*K13 -> -5.5649107 | I14: =I13+H14 -> 72.072781 | J14: =D14+H14 -> 2.8604263 | K14: =K13+J14 -> 826.20301
A15: 4 | B15: =Mu*dt -> 0.010233088 | C15: =C14*(1+B15) -> 760.10287 | D15: =K14*B15 -> 8.454608 | E15: =NORMINV(RAND(),0,1) -> -0.20423241 | F15: =E15*SQRT(dt) -> -0.02832194 | G15: =Sigma*F15 -> -0.0058391622 | H15: =G15*K14 -> -4.8243334 | I15: =I14+H15 -> 67.248448 | J15: =D15+H15 -> 3.6302746 | K15: =K14+J15 -> 829.83329
A16: 5 | B16: =Mu*dt -> 0.010233088 | C16: =C15*(1+B16) -> 767.88107 | D16: =K15*B16 -> 8.4917569 | E16: =NORMINV(RAND(),0,1) -> 1.3661201 | F16: =E16*SQRT(dt) -> 0.18944678 | G16: =Sigma*F16 -> 0.039058428 | H16: =G16*K15 -> 32.411984 | I16: =I15+H16 -> 99.660432 | J16: =D16+H16 -> 40.903741 | K16: =K15+J16 -> 870.73703
A17: 6 | B17: =Mu*dt -> 0.010233088 | C17: =C16*(1+B17) -> 775.73886 | D17: =K16*B17 -> 8.9103284 | E17: =NORMINV(RAND(),0,1) -> -0.4063869 | F17: =E17*SQRT(dt) -> -0.056355724 | G17: =Sigma*F17 -> -0.011618915 | H17: =G17*K16 -> -10.11702 | I17: =I16+H17 -> 89.543412 | J17: =D17+H17 -> -1.2066911 | K17: =K16+J17 -> 869.53034
A18: 7 | B18: =Mu*dt -> 0.010233088 | C18: =C17*(1+B18) -> 783.67707 | D18: =K17*B18 -> 8.8979803 | E18: =NORMINV(RAND(),0,1) -> -0.43170068 | F18: =E18*SQRT(dt) -> -0.059866113 | G18: =Sigma*F18 -> -0.012342655 | H18: =G18*K17 -> -10.732313 | I18: =I17+H18 -> 78.811099 | J18: =D18+H18 -> -1.8343331 | K18: =K17+J18 -> 867.696
A19: 8 | B19: =Mu*dt -> 0.010233088 | C19: =C18*(1+B19) -> 791.6965 | D19: =K18*B19 -> 8.8792094 | E19: =NORMINV(RAND(),0,1) -> 0.0043930166 | F19: =E19*SQRT(dt) -> 0.00060920179 | G19: =Sigma*F19 -> 0.00012559973 | H19: =G19*K18 -> 0.10898239 | I19: =I18+H19 -> 78.920081 | J19: =D19+H19 -> 8.9881918 | K19: =K18+J19 -> 876.68419
A20: 9 | B20: =Mu*dt -> 0.010233088 | C20: =C19*(1+B20) -> 799.798 | D20: =K19*B20 -> 8.9711863 | E20: =NORMINV(RAND(),0,1) -> 0.62253903 | F20: =E20*SQRT(dt) -> 0.086330631 | G20: =Sigma*F20 -> 0.017798871 | H20: =G20*K19 -> 15.603989 | I20: =I19+H20 -> 94.52407 | J20: =D20+H20 -> 24.575175 | K20: =K19+J20 -> 901.25937
A21: 10 | B21: =Mu*dt -> 0.010233088 | C21: =C20*(1+B21) -> 807.98241 | D21: =K20*B21 -> 9.2226663 | E21: =NORMINV(RAND(),0,1) -> -0.53951408 | F21: =E21*SQRT(dt) -> -0.074817142 | G21: =Sigma*F21 -> -0.015425124 | H21: =G21*K20 -> -13.902037 | I21: =I20+H21 -> 80.622033 | J21: =D21+H21 -> -4.679371 | K21: =K20+J21 -> 896.58
A22: 11 | B22: =Mu*dt -> 0.010233088 | C22: =C21*(1+B22) -> 816.25056 | D22: =K21*B22 -> 9.1747818 | E22: =NORMINV(RAND(),0,1) -> -0.13736194 | F22: =E22*SQRT(dt) -> -0.019048674 | G22: =Sigma*F22 -> -0.0039272838 | H22: =G22*K21 -> -3.5211241 | I22: =I21+H22 -> 77.100909 | J22: =D22+H22 -> 5.6536577 | K22: =K21+J22 -> 902.23366
A23: 12 | B23: =Mu*dt -> 0.010233088 | C23: =C22*(1+B23) -> 824.60333 | D23: =K22*B23 -> 9.2326362 | E23: =NORMINV(RAND(),0,1) -> -0.43723103 | F23: =E23*SQRT(dt) -> -0.060633034 | G23: =Sigma*F23 -> -0.012500772 | H23: =G23*K22 -> -11.278618 | I23: =I22+H23 -> 65.822291 | J23: =D23+H23 -> -2.0459813 | K23: =K22+J23 -> 900.18768
... A51: 40 | B51: =Mu*dt -> 0.010233088 | C51: =C50*(1+B51) -> 1096.6033 | D51: =K50*B51 -> 12.97696 | E51: =NORMINV(RAND(),0,1) -> -2.3341927 | F51: =E51*SQRT(dt) -> -0.32369429 | G51: =Sigma*F51 -> -0.06673637 | H51: =G51*K50 -> -84.63088 | I51: =I50+H51 -> 70.418397 | J51: =D51+H51 -> -71.65392 | K51: =K50+J51 -> 1196.4834

Sheet GBM_Multi
E1: Example with 500 draws and 3 variables. | J1: Average | K1: =AVERAGE(E$3:E$501) -> #NAME? | L1: =AVERAGE(F$3:F$501) -> #NAME? | M1: =AVERAGE(G$3:G$501) -> #NAME? | P1: Change in portolio | R1: Sorted
A2: Correlation Matrix | E2: =MultivarXs(3, 500, correlation matrix, mean vector, SD vector) | J2: SD pop | K2: =STDEVP(E$3:E$501) -> #NAME? | L2: =STDEVP(F$3:F$501) -> #NAME? | M2: =STDEVP(G$3:G$501) -> #NAME?
A3: 1 | E3: {=MultivarXs(3, 500, A$3:C$5, A$7:A$9, B$7:B$9)} -> #NAME? | F3: #NAME? | G3: #NAME? | P3: =1430*E3+435*F3+2412*G3 -> #NAME? | R3: {=_xlfn._xlws.SORT(P3:P501)} -> #NAME?
A4: 0.40502569 | B4: 1 | E4: #NAME? | F4: #NAME? | G4: #NAME? | K4: Correlation Matrix | P4: =1430*E4+435*F4+2412*G4 -> #NAME? | R4: #NAME?
A5: 0.44176033 | B5: -0.015442 | C5: 1 | E5: #NAME? | F5: #NAME? | G5: #NAME? | K5: =CORREL(E$3:E$501,E$3:E$501) -> #NAME? | P5: =1430*E5+435*F5+2412*G5 -> #NAME? | R5: #NAME?
A6: Mean | B6: SD | E6: #NAME? | F6: #NAME? | G6: #NAME? | K6: =CORREL(F$3:F$501,E$3:E$501) -> #NAME? | L6: =CORREL(F$3:F$501,F$3:F$501) -> #NAME? | P6: =1430*E6+435*F6+2412*G6 -> #NAME? | R6: #NAME?
A7: 0.0029670067 | B7: 0.019270962 | E7: #NAME? | F7: #NAME? | G7: #NAME? | K7: =CORREL(G$3:G$501,E$3:E$501) -> #NAME? | L7: =CORREL(G$3:G$501,F$3:F$501) -> #NAME? | M7: =CORREL(G$3:G$501,G$3:G$501) -> #NAME? | P7: =1430*E7+435*F7+2412*G7 -> #NAME? | R7: #NAME?
A8: 0.0034187514 | B8: 0.029240915 | E8: #NAME? | F8: #NAME? | G8: #NAME? | P8: =1430*E8+435*F8+2412*G8 -> #NAME? | R8: #NAME?
A9: 0.0015970212 | B9: 0.039779809 | E9: #NAME? | F9: #NAME? | G9: #NAME? | P9: =1430*E9+435*F9+2412*G9 -> #NAME? | R9: #NAME?
E10: #NAME? | F10: #NAME? | G10: #NAME? | P10: =1430*E10+435*F10+2412*G10 -> #NAME? | R10: #NAME?
E11: #NAME? | F11: #NAME? | G11: #NAME? | P11: =1430*E11+435*F11+2412*G11 -> #NAME? | R11: #NAME?
E12: #NAME? | F12: #NAME? | G12: #NAME? | P12: =1430*E12+435*F12+2412*G12 -> #NAME? | R12: #NAME?
E13: #NAME? | F13: #NAME? | G13: #NAME? | P13: =1430*E13+435*F13+2412*G13 -> #NAME? | R13: #NAME?
E14: #NAME? | F14: #NAME? | G14: #NAME? | P14: =1430*E14+435*F14+2412*G14 -> #NAME? | R14: #NAME?
E15: #NAME? | F15: #NAME? | G15: #NAME? | P15: =1430*E15+435*F15+2412*G15 -> #NAME? | R15: #NAME?
E16: #NAME? | F16: #NAME? | G16: #NAME? | P16: =1430*E16+435*F16+2412*G16 -> #NAME? | R16: #NAME?
E17: #NAME? | F17: #NAME? | G17: #NAME? | P17: =1430*E17+435*F17+2412*G17 -> #NAME? | R17: #NAME?
E18: #NAME? | F18: #NAME? | G18: #NAME? | P18: =1430*E18+435*F18+2412*G18 -> #NAME? | R18: #NAME?
E19: #NAME? | F19: #NAME? | G19: #NAME? | P19: =1430*E19+435*F19+2412*G19 -> #NAME? | R19: #NAME?
E20: #NAME? | F20: #NAME? | G20: #NAME? | P20: =1430*E20+435*F20+2412*G20 -> #NAME? | R20: #NAME?
E21: #NAME? | F21: #NAME? | G21: #NAME? | P21: =1430*E21+435*F21+2412*G21 -> #NAME? | R21: #NAME?
... E91: #NAME? | F91: #NAME? | G91: #NAME? | P91: =1430*E91+435*F91+2412*G91 -> #NAME? | R91: #NAME?
E92: {=MultivarXs(3, 500, A$3:C$5, A$7:A$9, B$7:B$9)} -> #NAME? | F92: #NAME? | G92: #NAME? | P92: =1430*E92+435*F92+2412*G92 -> #NAME? | R92: #NAME?
E93: {=MultivarXs(3, 500, A$3:C$5, A$7:A$9, B$7:B$9)} -> #NAME? | F93: #NAME? | G93: #NAME? | P93: =1430*E93+435*F93+2412*G93 -> #NAME? | R93: #NAME?
E94: {=MultivarXs(3, 500, A$3:C$5, A$7:A$9, B$7:B$9)} -> #NAME? | F94: #NAME? | G94: #NAME? | P94: =1430*E94+435*F94+2412*G94 -> #NAME? | R94: #NAME?
E95: {=MultivarXs(3, 500, A$3:C$5, A$7:A$9, B$7:B$9)} -> #NAME? | F95: #NAME? | G95: #NAME? | P95: =1430*E95+435*F95+2412*G95 -> #NAME? | R95: #NAME?
E96: {=MultivarXs(3, 500, A$3:C$5, A$7:A$9, B$7:B$9)} -> #NAME? | F96: #NAME? | G96: #NAME? | P96: =1430*E96+435*F96+2412*G96 -> #NAME? | R96: #NAME?
E97: {=MultivarXs(3, 500, A$3:C$5, A$7:A$9, B$7:B$9)} -> #NAME? | F97: #NAME? | G97: #NAME? | P97: =1430*E97+435*F97+2412*G97 -> #NAME? | R97: #NAME?
E98: {=MultivarXs(3, 500, A$3:C$5, A$7:A$9, B$7:B$9)} -> #NAME? | F98: #NAME? | G98: #NAME? | P98: =1430*E98+435*F98+2412*G98 -> #NAME? | R98: #NAME?
E99: {=MultivarXs(3, 500, A$3:C$5, A$7:A$9, B$7:B$9)} -> #NAME? | F99: #NAME? | G99: #NAME? | P99: =1430*E99+435*F99+2412*G99 -> #NAME? | R99: #NAME?
E100: {=MultivarXs(3, 500, A$3:C$5, A$7:A$9, B$7:B$9)} -> #NAME? | F100: #NAME? | G100: #NAME? | P100: =1430*E100+435*F100+2412*G100 -> #NAME? | R100: #NAME?
E101: {=MultivarXs(3, 500, A$3:C$5, A$7:A$9, B$7:B$9)} -> #NAME? | F101: #NAME? | G101: #NAME? | P101: =1430*E101+435*F101+2412*G101 -> #NAME? | R101: #NAME?
E102: {=MultivarXs(3, 500, A$3:C$5, A$7:A$9, B$7:B$9)} -> #NAME? | F102: #NAME? | G102: #NAME? | P102: =1430*E102+435*F102+2412*G102 -> #NAME? | R102: #NAME?
E103: {=MultivarXs(3, 500, A$3:C$5, A$7:A$9, B$7:B$9)} -> #NAME? | F103: #NAME? | G103: #NAME? | P103: =1430*E103+435*F103+2412*G103 -> #NAME? | R103: #NAME?
... E501: {=MultivarXs(3, 500, A$3:C$5, A$7:A$9, B$7:B$9)} -> #NAME? | F501: #NAME? | G501: #NAME? | P501: =1430*E501+435*F501+2412*G501 -> #NAME? | R501: #NAME?
